Workbook
Name Faktorer: #REF!
Name KONTOR: '4. Reduktionsfaktorer, LENI-tal'!$Q$13:$Q$23
Name Omvandlingsfaktorer: #REF!
Name SJUKHUS: '4. Reduktionsfaktorer, LENI-tal'!$T$13:$T$23
Name SKOLA: #REF!
Name SKOLA_OCH_RESTAURANG: '4. Reduktionsfaktorer, LENI-tal'!$R$13:$R$23
Name SPORTHALL: '4. Reduktionsfaktorer, LENI-tal'!$S$13:$S$23
Name SPORTHALLAR: #REF!
Name STYRNING: #REF!

Sheet 1. Introduktion
A1: (PW: LCC)
G2: LCC-kalkyl för upphandling av inomhusbelysning
G3: Version 3.0
G4: Datum: 2024-12-17
B9: Introduktion
B11: Generella instruktioner kring hur verktyget används.
B14: Versionsinformation
B16: Upphandlingsmyndighetens LCC-verktyg har utvecklats i omgångar sedan 2009.
B19: Ändringar i senaste versionen (v 3.2) av LCC-verktyg Inomhusbelysning: Flik 1 har uppdaterats med denna versionsinformation och information om nytt lösenordsskydd, texter är genomgångna och uppdaterade. Flik 2 (4 alt) är nu utan makrofunktion att lägga till/ta bort rumstyper och armaturtyper. Ny funktion med förinställda byggnadstyper och rumstyper som hämtar reduktionsfaktorer från flik 4. Observera att funktionalitet förloras om värdet skrivs över. (Kursiverat är ändrat sedan v 3.0).Version 3.2 har en ruta för drifttid som kan väljas från förinställda byggnadstyper, eller så kan ett eget värde skrivas in i raden under. Flik 3 är texter genomgångna och uppdaterade. Flik 4 har uppdaterats med riktlinjer för installerad effekt och jämförelsetal energianvändning (LENI-tal) enligt Ljus & Rum utgåva 4 (2022). Flik 5 har uppdaterats med aktuella beräkningsfaktorer klimat samt källor.
H23: Vad är LCC?
H24: LCC står för "Life Cycle Costs" - livscykelkostnader. Med hjälp av en LCC-beräkning erhålls en totalbild över varans, tjänstens eller anläggningens kostnader under hela dess nyttjandetid. Jämförelser mellan olika produktalternativ och lösningar kan göras. Livscykelkostnadsperspektivet kan med fördel användas i flera delar av inköpsprocessen och även i det strategiska arbetet med organisationens budget.
H25: Läs mer om LCC på Upphandlingsmyndighetens webbplats
H27: Hur ska jag använda detta LCC-verktyg?
H28: Detta LCC-verktyg är specifikt utvecklat att användas vid upphandling av inomhusbelysning. Verktyget kan med fördel användas både i behovsanalysen, vid kravställande och i anbudsutvärderingen. I behovsanalysen kan verktyget användas för att i ett tidigt skede få en översikt över vilka typer av kostnader som förekommer under nyttjandetiden och hur stora dessa kostnader är. För en belysningsanläggning utgör exempelvis driftskostnaden för energi en stor kostnadspost. Detta kan till exempel testas med olika scenarier för energiprisökning, eller med olika styrfunktioner. Att använda verktyget på det sättet ökar medvetenheten i organisationen och kan vara ett bra underlag till viktiga vägval inför upphandlingen. Använd gärna kalkylparametrarna som en checklista, exempelvis inför leverantörsdialogen. När LCC-beräkning ställs som krav i upphandlingen måste förfrågningsunderlaget beskriva de parametrar som ska ingå i beräkningen, hur dessa ska dokumenteras och vilka mätmetoder som ska användas. Använd gärna kriteriet "belysningsanläggningens livscykelkostnad (LCC)" som kan laddas hem genom Upphandlingsmyndighetens kriterietjänst. En tumregel är att vid kravställande endast ta med de stora kostnadsposterna eller de kostnader som förväntas skilja sig åt mellan olika leverantörer.
B29: Lösenordsskydd Varje flik i Excelfilen är skyddad med ett lösenord, för att förhindra oavsiktliga förändringar i LCC-kalkylen. - För att låsa upp välj Granska > Ta bort bladets skydd. | H29: Vid anbudsutvärdering vägs livscykelkostnaden in som en parameter för bedömning av det ekonomiskt mest fördelaktiga anbudet. Kvalitativa krav på belysningsanläggningen, såsom ljuskvalitet, ingår inte i kalkylen utan måste kravställas i förfrågningsunderlaget. I detta LCC-verktyg finns även möjlighet till jämförelse av alternativens klimatpåverkan från energianvändningen under nyttjandetiden.
B30: - Lösenordet är LCC.
H31: Hur är LCC-verktyget uppbyggt?
H32: Verktyget består av 7 flikar: 1. Introduktion: generella instruktioner kring hur verktyget används. 2. LCC-kalkyl A1-4: Fyra stycken kalkylblad där LCC-beräkningen utförs med standardiserade parametrar. Ett blad används per anläggning. 3. Kalkylparametrar: Samlade instruktioner kring vad kalkylparametrarna innebär och vad som ska ingå. 4. Reduktionsfaktorer styrning: reduktionsfaktorer för belysningsstyrning, hämtade från Belysningsbranschens handbok "Ljus & Rum". 5. Beräkningsfaktorer klimatpåverkan: frivilliga indata för att kunna beräkna klimatpåverkan från elenergi. 6. Resultat: visuell översikt över LCC-beräkningens resultat. 7. Svarsformulär: svarsformulär som leverantören bifogar anbudet. Beskrivning av anläggningen med rumstyper och storlek på dessa måste göras i förfrågningsunderlaget. Beställaren (upphandlande myndighet) anger kalkylförutsättningar och information kring användning; detta utgör grunden för beräkningen. Läs mer om kalkylförutsättningar och ekonomiska parametrar på länken under rubriken Vad är LCC ovan. Anbudsgivaren fyller i resterande uppgifter i kalkylbladet (indata) enligt de standarder eller instruktioner som anges. Kostnaderna anges utan moms. I kolumnerna anges de olika rumstyper som förekommer i belysningsanläggningen enligt beställarens beskrivning i förfrågningsunderlaget. Rummen summeras i slutet och LCC-resultatet för hela anläggningen visas. Ett kalkylblad per anläggning används. Alternativa investeringslösningar, om sådana finns, anges i kalkylblad A2-A4. Anbudsgivaren fyller i svarsformuläret (ett formulär per typrum) och bifogar den till beställaren. Beställaren kan sedan föra in varje anbudsgivares uppgifter i ett nytt kalkylblad för att kunna jämföra alla anbud i resultatfliken. Beställaren kan även använda ett av kalkylbladen A1-A4 för att fylla i information kring befintlig anläggning om sådan finns; detta för att tydliggöra förbättringarna med en ny eller renoverad anläggning. LCC-kalkylerna är baserade på nuvärdesmetoden för att kunna omräkna framtida kostnader till dagens värde. Omräkningsfaktorer till nuvärde är inkluderade i formlerna. Kalkylränta, elpris och användningstid är exempel på parametrar som kan variera och som måste beslutas i den upphandlande organisationen. Kostnadsbilden påverkas beroende på valet av dessa parametrar, exempelvis innebär en hög ränta att pengarnas värde sjunker under kalkylperioden och vid låg ränta behåller pengarna sitt värde. En lång användningstid gör att driftskostnadernas betydelse ökar i kalkylen. För att få en förståelse för effekten på slutresultatet vid olika scenarier, t.ex. energiprisökning, kan kalkylen testas med ett antal olika värden.
H33: Kontakt
H34: Upphandlingsmyndigheten utvecklar och förvaltar LCC-verktygen som är frivilliga att använda inom såväl offentlig som privat sektor. Upphandlingsmyndigheten står för innehållet i denna version. Eventuella ändringar görs på eget ansvar. Vid frågor om verktyget kan du kontakta oss via vår frågeportal på www.upphandlingsmyndigheten.se.

Sheet 2. LCC A1
A1: (PW: LCC)
G2: LCC-kalkyl för upphandling av inomhusbelysning
G3: ='1. Introduktion'!G3 -> Version 3.0
G4: ='1. Introduktion'!G4 -> Datum: 2024-12-17
C8: LCC-kalkyl Anläggning alternativ 1
C10: Kalkylförutsättningar (anges av beställaren) | K10: Byggnadstyp | L10: 0
C11: PROJEKT: | F11: Projektnamn | K11: Kontor | L11: 2500
C12: DATUM: | F12: ÅÅÅÅ-MM-DD | K12: Skola, restaurang | L12: 2000
C13: HANDLÄGGARE: | F13: Namn | K13: Sporthall | L13: 4000
K14: Vård | L14: 5000
B15: 1.1 | C15: Tid kalkylen omfattar | I15: år
B16: 1.2 | C16: Kalkylränta | H16: 0.05 | K16: Indata till fält 16: Byggnadens driftitid h/ år
B17: 1.3 | C17: Elpris | I17: kr/kWh | K17: Byggnadstyp | L17: Byggnadstyp
B18: 1.4 | C18: Årlig prisförändring energi (frivillig) | K18: Eget värde för drifttid h/år
B19: 1.5 | C19: Klimatpåverkan energianvändning (frivillig) | I19: kgCO2/kwh | K19: Driftitd timmar per år | L19: =IF(ISBLANK($L$18),VLOOKUP($L$17,$K$10:$L$14,2),$L$18) -> 0
B20: 1.6 | C20: Drifttid | H20: =$L$19 -> 0 | I20: h/år
C22: Beskrivning av anläggningen och belysningsförslag
C24: BESKRIVNING AV ANLÄGGNINGEN (anges av beställaren)
C25: Byggnadstyp | I25: Byggnadstyp 1 | J25: Byggnadstyp 2 | K25: Byggnadstyp 3 | L25: Byggnadstyp 4 | M25: Byggnadstyp 5 | N25: Byggnadstyp 6 | O25: Byggnadstyp 7 | P25: Byggnadstyp 8 | Q25: Byggnadstyp 9 | R25: Byggnadstyp 10
C26: Byggnadstyp hjälprad | I26: =SUBSTITUTE(I25," ","_") -> Byggnadstyp_1 | J26: =SUBSTITUTE(J25," ","_") -> Byggnadstyp_2 | K26: =SUBSTITUTE(K25," ","_") -> Byggnadstyp_3 | L26: =SUBSTITUTE(L25," ","_") -> Byggnadstyp_4 | M26: =SUBSTITUTE(M25," ","_") -> Byggnadstyp_5 | N26: =SUBSTITUTE(N25," ","_") -> Byggnadstyp_6 | O26: =SUBSTITUTE(O25," ","_") -> Byggnadstyp_7 | P26: =SUBSTITUTE(P25," ","_") -> Byggnadstyp_8 | ... R26: =SUBSTITUTE(R25," ","_") -> Byggnadstyp_10
C27: Rumstyp (välj byggnadstyp ovan för att få lista med giltiga rumstyper) | I27: Rumstyp 1 | J27: Rumstyp 2 | K27: Rumstyp 3 | L27: Rumstyp 4 | M27: Rumstyp 5 | N27: Rumstyp 6 | O27: Rumstyp 7 | P27: Rumstyp 8 | Q27: Rumstyp 9 | R27: Rumstyp 10
C28: Antal rum av samma typ | H28: stk
C29: Antal kvadratmeter | H29: m2/rum
C30: BELYSNINGSFÖRSLAG (anges av anbudsgivaren)
C31: ARMATURTYP 1
B32: 2.1 | C32: Antal armaturer | H32: stk
B33: 2.2 | C33: Armaturpris | H33: kr/stk
B34: 2.3 | C34: Material- och arbetskostnader armatur | H34: kr/stk
B35: 2.4 | C35: Effekt per armatur, inkl. driftsförluster | H35: W/stk
B36: 2.5 | C36: Typ av styrning | I36: Ingen | J36: Ingen | K36: Ingen | L36: Ingen | M36: Ingen | N36: Ingen | O36: Ingen | P36: Ingen | Q36: Ingen | R36: Ingen
B37: 2.6 | C37: Reduktionsfaktor manuell styrning | I37: {=IFERROR(_xlfn.IFS(I$25='4. Reduktionsfaktorer, LENI-tal'!$Q$12,INDEX('4. Reduktionsfaktorer, LENI-tal'!$H$13:$O$23,MATCH(I$27,'4. Reduktionsfaktorer, LENI-tal'!$H$13:$H$23,0),3), I$25="SKOLA OCH RESTAURANG",INDEX('4. Reduktionsfaktorer, LENI-tal'!$H$24:$O$32,MATCH(I$27,'4. Reduktionsfaktorer, LENI-tal'!$H$24:$H$32,0),3), I$25='4. Reduktionsfaktorer, LENI-tal'!$S$12,INDEX('4. Reduktionsfaktorer, LENI-tal'!$H$33:$O$37,MATCH(I$27,'4. Reduktionsfaktorer, LENI-tal'!$H$33:$H$37,0),3), I$25='4. Reduktionsfaktorer, LENI-tal'!$T$12,INDEX('4. Reduktionsfaktorer, LENI-tal'!$H$38:$O$45,MATCH(I$27,'4. Reduktionsfaktorer, LENI-tal'!$H$38:$H$45,0),3)), "Fyll i byggnads- och rumstyp ovan")} -> Fyll i byggnads- och rumstyp ovan | J37: {=IFERROR(_xlfn.IFS(J$25='4. Reduktionsfaktorer, LENI-tal'!$Q$12,INDEX('4. Reduktionsfaktorer, LENI-tal'!$H$13:$O$23,MATCH(J$27,'4. Reduktionsfaktorer, LENI-tal'!$H$13:$H$23,0),3), J$25="SKOLA OCH RESTAURANG",INDEX('4. Reduktionsfaktorer, LENI-tal'!$H$24:$O$32,MATCH(J$27,'4. Reduktionsfaktorer, LENI-tal'!$H$24:$H$32,0),3), J$25='4. Reduktionsfaktorer, LENI-tal'!$S$12,INDEX('4. Reduktionsfaktorer, LENI-tal'!$H$33:$O$37,MATCH(J$27,'4. Reduktionsfaktorer, LENI-tal'!$H$33:$H$37,0),3), J$25='4. Reduktionsfaktorer, LENI-tal'!$T$12,INDEX('4. Reduktionsfaktorer, LENI-tal'!$H$38:$O$45,MATCH(J$27,'4. Reduktionsfaktorer, LENI-tal'!$H$38:$H$45,0),3)), "Fyll i byggnads- och rumstyp ovan")} -> Fyll i byggnads- och rumstyp ovan | K37: {=IFERROR(_xlfn.IFS(K$25='4. Reduktionsfaktorer, LENI-tal'!$Q$12,INDEX('4. Reduktionsfaktorer, LENI-tal'!$H$13:$O$23,MATCH(K$27,'4. Reduktionsfaktorer, LENI-tal'!$H$13:$H$23,0),3), K$25="SKOLA OCH RESTAURANG",INDEX('4. Reduktionsfaktorer, LENI-tal'!$H$24:$O$32,MATCH(K$27,'4. Reduktionsfaktorer, LENI-tal'!$H$24:$H$32,0),3), K$25='4. Reduktionsfaktorer, LENI-tal'!$S$12,INDEX('4. Reduktionsfaktorer, LENI-tal'!$H$33:$O$37,MATCH(K$27,'4. Reduktionsfaktorer, LENI-tal'!$H$33:$H$37,0),3), K$25='4. Reduktionsfaktorer, LENI-tal'!$T$12,INDEX('4. Reduktionsfaktorer, LENI-tal'!$H$38:$O$45,MATCH(K$27,'4. Reduktionsfaktorer, LENI-tal'!$H$38:$H$45,0),3)), "Fyll i byggnads- och rumstyp ovan")} -> Fyll i byggnads- och rumstyp ovan | L37: {=IFERROR(_xlfn.IFS(L$25='4. Reduktionsfaktorer, LENI-tal'!$Q$12,INDEX('4. Reduktionsfaktorer, LENI-tal'!$H$13:$O$23,MATCH(L$27,'4. Reduktionsfaktorer, LENI-tal'!$H$13:$H$23,0),3), L$25="SKOLA OCH RESTAURANG",INDEX('4. Reduktionsfaktorer, LENI-tal'!$H$24:$O$32,MATCH(L$27,'4. Reduktionsfaktorer, LENI-tal'!$H$24:$H$32,0),3), L$25='4. Reduktionsfaktorer, LENI-tal'!$S$12,INDEX('4. Reduktionsfaktorer, LENI-tal'!$H$33:$O$37,MATCH(L$27,'4. Reduktionsfaktorer, LENI-tal'!$H$33:$H$37,0),3), L$25='4. Reduktionsfaktorer, LENI-tal'!$T$12,INDEX('4. Reduktionsfaktorer, LENI-tal'!$H$38:$O$45,MATCH(L$27,'4. Reduktionsfaktorer, LENI-tal'!$H$38:$H$45,0),3)), "Fyll i byggnads- och rumstyp ovan")} -> Fyll i byggnads- och rumstyp ovan | M37: {=IFERROR(_xlfn.IFS(M$25='4. Reduktionsfaktorer, LENI-tal'!$Q$12,INDEX('4. Reduktionsfaktorer, LENI-tal'!$H$13:$O$23,MATCH(M$27,'4. Reduktionsfaktorer, LENI-tal'!$H$13:$H$23,0),3), M$25="SKOLA OCH RESTAURANG",INDEX('4. Reduktionsfaktorer, LENI-tal'!$H$24:$O$32,MATCH(M$27,'4. Reduktionsfaktorer, LENI-tal'!$H$24:$H$32,0),3), M$25='4. Reduktionsfaktorer, LENI-tal'!$S$12,INDEX('4. Reduktionsfaktorer, LENI-tal'!$H$33:$O$37,MATCH(M$27,'4. Reduktionsfaktorer, LENI-tal'!$H$33:$H$37,0),3), M$25='4. Reduktionsfaktorer, LENI-tal'!$T$12,INDEX('4. Reduktionsfaktorer, LENI-tal'!$H$38:$O$45,MATCH(M$27,'4. Reduktionsfaktorer, LENI-tal'!$H$38:$H$45,0),3)), "Fyll i byggnads- och rumstyp ovan")} -> Fyll i byggnads- och rumstyp ovan | N37: {=IFERROR(_xlfn.IFS(N$25='4. Reduktionsfaktorer, LENI-tal'!$Q$12,INDEX('4. Reduktionsfaktorer, LENI-tal'!$H$13:$O$23,MATCH(N$27,'4. Reduktionsfaktorer, LENI-tal'!$H$13:$H$23,0),3), N$25="SKOLA OCH RESTAURANG",INDEX('4. Reduktionsfaktorer, LENI-tal'!$H$24:$O$32,MATCH(N$27,'4. Reduktionsfaktorer, LENI-tal'!$H$24:$H$32,0),3), N$25='4. Reduktionsfaktorer, LENI-tal'!$S$12,INDEX('4. Reduktionsfaktorer, LENI-tal'!$H$33:$O$37,MATCH(N$27,'4. Reduktionsfaktorer, LENI-tal'!$H$33:$H$37,0),3), N$25='4. Reduktionsfaktorer, LENI-tal'!$T$12,INDEX('4. Reduktionsfaktorer, LENI-tal'!$H$38:$O$45,MATCH(N$27,'4. Reduktionsfaktorer, LENI-tal'!$H$38:$H$45,0),3)), "Fyll i byggnads- och rumstyp ovan")} -> Fyll i byggnads- och rumstyp ovan | O37: {=IFERROR(_xlfn.IFS(O$25='4. Reduktionsfaktorer, LENI-tal'!$Q$12,INDEX('4. Reduktionsfaktorer, LENI-tal'!$H$13:$O$23,MATCH(O$27,'4. Reduktionsfaktorer, LENI-tal'!$H$13:$H$23,0),3), O$25="SKOLA OCH RESTAURANG",INDEX('4. Reduktionsfaktorer, LENI-tal'!$H$24:$O$32,MATCH(O$27,'4. Reduktionsfaktorer, LENI-tal'!$H$24:$H$32,0),3), O$25='4. Reduktionsfaktorer, LENI-tal'!$S$12,INDEX('4. Reduktionsfaktorer, LENI-tal'!$H$33:$O$37,MATCH(O$27,'4. Reduktionsfaktorer, LENI-tal'!$H$33:$H$37,0),3), O$25='4. Reduktionsfaktorer, LENI-tal'!$T$12,INDEX('4. Reduktionsfaktorer, LENI-tal'!$H$38:$O$45,MATCH(O$27,'4. Reduktionsfaktorer, LENI-tal'!$H$38:$H$45,0),3)), "Fyll i byggnads- och rumstyp ovan")} -> Fyll i byggnads- och rumstyp ovan | P37: {=IFERROR(_xlfn.IFS(P$25='4. Reduktionsfaktorer, LENI-tal'!$Q$12,INDEX('4. Reduktionsfaktorer, LENI-tal'!$H$13:$O$23,MATCH(P$27,'4. Reduktionsfaktorer, LENI-tal'!$H$13:$H$23,0),3), P$25="SKOLA OCH RESTAURANG",INDEX('4. Reduktionsfaktorer, LENI-tal'!$H$24:$O$32,MATCH(P$27,'4. Reduktionsfaktorer, LENI-tal'!$H$24:$H$32,0),3), P$25='4. Reduktionsfaktorer, LENI-tal'!$S$12,INDEX('4. Reduktionsfaktorer, LENI-tal'!$H$33:$O$37,MATCH(P$27,'4. Reduktionsfaktorer, LENI-tal'!$H$33:$H$37,0),3), P$25='4. Reduktionsfaktorer, LENI-tal'!$T$12,INDEX('4. Reduktionsfaktorer, LENI-tal'!$H$38:$O$45,MATCH(P$27,'4. Reduktionsfaktorer, LENI-tal'!$H$38:$H$45,0),3)), "Fyll i byggnads- och rumstyp ovan")} -> Fyll i byggnads- och rumstyp ovan | ... R37: {=IFERROR(_xlfn.IFS(R$25='4. Reduktionsfaktorer, LENI-tal'!$Q$12,INDEX('4. Reduktionsfaktorer, LENI-tal'!$H$13:$O$23,MATCH(R$27,'4. Reduktionsfaktorer, LENI-tal'!$H$13:$H$23,0),3), R$25="SKOLA OCH RESTAURANG",INDEX('4. Reduktionsfaktorer, LENI-tal'!$H$24:$O$32,MATCH(R$27,'4. Reduktionsfaktorer, LENI-tal'!$H$24:$H$32,0),3), R$25='4. Reduktionsfaktorer, LENI-tal'!$S$12,INDEX('4. Reduktionsfaktorer, LENI-tal'!$H$33:$O$37,MATCH(R$27,'4. Reduktionsfaktorer, LENI-tal'!$H$33:$H$37,0),3), R$25='4. Reduktionsfaktorer, LENI-tal'!$T$12,INDEX('4. Reduktionsfaktorer, LENI-tal'!$H$38:$O$45,MATCH(R$27,'4. Reduktionsfaktorer, LENI-tal'!$H$38:$H$45,0),3)), "Fyll i byggnads- och rumstyp ovan")} -> Fyll i byggnads- och rumstyp ovan
B38: 2.7 | C38: Reduktionsfaktor närvaro-/frånvarostyrning | I38: {=IFERROR(_xlfn.IFS(I$25='4. Reduktionsfaktorer, LENI-tal'!$Q$12,INDEX('4. Reduktionsfaktorer, LENI-tal'!$H$13:$O$23,MATCH(I$27,'4. Reduktionsfaktorer, LENI-tal'!$H$13:$H$23,0),4), I$25="SKOLA OCH RESTAURANG",INDEX('4. Reduktionsfaktorer, LENI-tal'!$H$24:$O$32,MATCH(I$27,'4. Reduktionsfaktorer, LENI-tal'!$H$24:$H$32,0),4), I$25='4. Reduktionsfaktorer, LENI-tal'!$S$12,INDEX('4. Reduktionsfaktorer, LENI-tal'!$H$33:$O$37,MATCH(I$27,'4. Reduktionsfaktorer, LENI-tal'!$H$33:$H$37,0),4), I$25='4. Reduktionsfaktorer, LENI-tal'!$T$12,INDEX('4. Reduktionsfaktorer, LENI-tal'!$H$38:$O$45,MATCH(I$27,'4. Reduktionsfaktorer, LENI-tal'!$H$38:$H$45,0),4)), "Fyll i byggnads- och rumstyp ovan")} -> Fyll i byggnads- och rumstyp ovan | J38: {=IFERROR(_xlfn.IFS(J$25='4. Reduktionsfaktorer, LENI-tal'!$Q$12,INDEX('4. Reduktionsfaktorer, LENI-tal'!$H$13:$O$23,MATCH(J$27,'4. Reduktionsfaktorer, LENI-tal'!$H$13:$H$23,0),4), J$25="SKOLA OCH RESTAURANG",INDEX('4. Reduktionsfaktorer, LENI-tal'!$H$24:$O$32,MATCH(J$27,'4. Reduktionsfaktorer, LENI-tal'!$H$24:$H$32,0),4), J$25='4. Reduktionsfaktorer, LENI-tal'!$S$12,INDEX('4. Reduktionsfaktorer, LENI-tal'!$H$33:$O$37,MATCH(J$27,'4. Reduktionsfaktorer, LENI-tal'!$H$33:$H$37,0),4), J$25='4. Reduktionsfaktorer, LENI-tal'!$T$12,INDEX('4. Reduktionsfaktorer, LENI-tal'!$H$38:$O$45,MATCH(J$27,'4. Reduktionsfaktorer, LENI-tal'!$H$38:$H$45,0),4)), "Fyll i byggnads- och rumstyp ovan")} -> Fyll i byggnads- och rumstyp ovan | K38: {=IFERROR(_xlfn.IFS(K$25='4. Reduktionsfaktorer, LENI-tal'!$Q$12,INDEX('4. Reduktionsfaktorer, LENI-tal'!$H$13:$O$23,MATCH(K$27,'4. Reduktionsfaktorer, LENI-tal'!$H$13:$H$23,0),4), K$25="SKOLA OCH RESTAURANG",INDEX('4. Reduktionsfaktorer, LENI-tal'!$H$24:$O$32,MATCH(K$27,'4. Reduktionsfaktorer, LENI-tal'!$H$24:$H$32,0),4), K$25='4. Reduktionsfaktorer, LENI-tal'!$S$12,INDEX('4. Reduktionsfaktorer, LENI-tal'!$H$33:$O$37,MATCH(K$27,'4. Reduktionsfaktorer, LENI-tal'!$H$33:$H$37,0),4), K$25='4. Reduktionsfaktorer, LENI-tal'!$T$12,INDEX('4. Reduktionsfaktorer, LENI-tal'!$H$38:$O$45,MATCH(K$27,'4. Reduktionsfaktorer, LENI-tal'!$H$38:$H$45,0),4)), "Fyll i byggnads- och rumstyp ovan")} -> Fyll i byggnads- och rumstyp ovan | L38: {=IFERROR(_xlfn.IFS(L$25='4. Reduktionsfaktorer, LENI-tal'!$Q$12,INDEX('4. Reduktionsfaktorer, LENI-tal'!$H$13:$O$23,MATCH(L$27,'4. Reduktionsfaktorer, LENI-tal'!$H$13:$H$23,0),4), L$25="SKOLA OCH RESTAURANG",INDEX('4. Reduktionsfaktorer, LENI-tal'!$H$24:$O$32,MATCH(L$27,'4. Reduktionsfaktorer, LENI-tal'!$H$24:$H$32,0),4), L$25='4. Reduktionsfaktorer, LENI-tal'!$S$12,INDEX('4. Reduktionsfaktorer, LENI-tal'!$H$33:$O$37,MATCH(L$27,'4. Reduktionsfaktorer, LENI-tal'!$H$33:$H$37,0),4), L$25='4. Reduktionsfaktorer, LENI-tal'!$T$12,INDEX('4. Reduktionsfaktorer, LENI-tal'!$H$38:$O$45,MATCH(L$27,'4. Reduktionsfaktorer, LENI-tal'!$H$38:$H$45,0),4)), "Fyll i byggnads- och rumstyp ovan")} -> Fyll i byggnads- och rumstyp ovan | M38: {=IFERROR(_xlfn.IFS(M$25='4. Reduktionsfaktorer, LENI-tal'!$Q$12,INDEX('4. Reduktionsfaktorer, LENI-tal'!$H$13:$O$23,MATCH(M$27,'4. Reduktionsfaktorer, LENI-tal'!$H$13:$H$23,0),4), M$25="SKOLA OCH RESTAURANG",INDEX('4. Reduktionsfaktorer, LENI-tal'!$H$24:$O$32,MATCH(M$27,'4. Reduktionsfaktorer, LENI-tal'!$H$24:$H$32,0),4), M$25='4. Reduktionsfaktorer, LENI-tal'!$S$12,INDEX('4. Reduktionsfaktorer, LENI-tal'!$H$33:$O$37,MATCH(M$27,'4. Reduktionsfaktorer, LENI-tal'!$H$33:$H$37,0),4), M$25='4. Reduktionsfaktorer, LENI-tal'!$T$12,INDEX('4. Reduktionsfaktorer, LENI-tal'!$H$38:$O$45,MATCH(M$27,'4. Reduktionsfaktorer, LENI-tal'!$H$38:$H$45,0),4)), "Fyll i byggnads- och rumstyp ovan")} -> Fyll i byggnads- och rumstyp ovan | N38: {=IFERROR(_xlfn.IFS(N$25='4. Reduktionsfaktorer, LENI-tal'!$Q$12,INDEX('4. Reduktionsfaktorer, LENI-tal'!$H$13:$O$23,MATCH(N$27,'4. Reduktionsfaktorer, LENI-tal'!$H$13:$H$23,0),4), N$25="SKOLA OCH RESTAURANG",INDEX('4. Reduktionsfaktorer, LENI-tal'!$H$24:$O$32,MATCH(N$27,'4. Reduktionsfaktorer, LENI-tal'!$H$24:$H$32,0),4), N$25='4. Reduktionsfaktorer, LENI-tal'!$S$12,INDEX('4. Reduktionsfaktorer, LENI-tal'!$H$33:$O$37,MATCH(N$27,'4. Reduktionsfaktorer, LENI-tal'!$H$33:$H$37,0),4), N$25='4. Reduktionsfaktorer, LENI-tal'!$T$12,INDEX('4. Reduktionsfaktorer, LENI-tal'!$H$38:$O$45,MATCH(N$27,'4. Reduktionsfaktorer, LENI-tal'!$H$38:$H$45,0),4)), "Fyll i byggnads- och rumstyp ovan")} -> Fyll i byggnads- och rumstyp ovan | O38: {=IFERROR(_xlfn.IFS(O$25='4. Reduktionsfaktorer, LENI-tal'!$Q$12,INDEX('4. Reduktionsfaktorer, LENI-tal'!$H$13:$O$23,MATCH(O$27,'4. Reduktionsfaktorer, LENI-tal'!$H$13:$H$23,0),4), O$25="SKOLA OCH RESTAURANG",INDEX('4. Reduktionsfaktorer, LENI-tal'!$H$24:$O$32,MATCH(O$27,'4. Reduktionsfaktorer, LENI-tal'!$H$24:$H$32,0),4), O$25='4. Reduktionsfaktorer, LENI-tal'!$S$12,INDEX('4. Reduktionsfaktorer, LENI-tal'!$H$33:$O$37,MATCH(O$27,'4. Reduktionsfaktorer, LENI-tal'!$H$33:$H$37,0),4), O$25='4. Reduktionsfaktorer, LENI-tal'!$T$12,INDEX('4. Reduktionsfaktorer, LENI-tal'!$H$38:$O$45,MATCH(O$27,'4. Reduktionsfaktorer, LENI-tal'!$H$38:$H$45,0),4)), "Fyll i byggnads- och rumstyp ovan")} -> Fyll i byggnads- och rumstyp ovan | P38: {=IFERROR(_xlfn.IFS(P$25='4. Reduktionsfaktorer, LENI-tal'!$Q$12,INDEX('4. Reduktionsfaktorer, LENI-tal'!$H$13:$O$23,MATCH(P$27,'4. Reduktionsfaktorer, LENI-tal'!$H$13:$H$23,0),4), P$25="SKOLA OCH RESTAURANG",INDEX('4. Reduktionsfaktorer, LENI-tal'!$H$24:$O$32,MATCH(P$27,'4. Reduktionsfaktorer, LENI-tal'!$H$24:$H$32,0),4), P$25='4. Reduktionsfaktorer, LENI-tal'!$S$12,INDEX('4. Reduktionsfaktorer, LENI-tal'!$H$33:$O$37,MATCH(P$27,'4. Reduktionsfaktorer, LENI-tal'!$H$33:$H$37,0),4), P$25='4. Reduktionsfaktorer, LENI-tal'!$T$12,INDEX('4. Reduktionsfaktorer, LENI-tal'!$H$38:$O$45,MATCH(P$27,'4. Reduktionsfaktorer, LENI-tal'!$H$38:$H$45,0),4)), "Fyll i byggnads- och rumstyp ovan")} -> Fyll i byggnads- och rumstyp ovan | ... R38: {=IFERROR(_xlfn.IFS(R$25='4. Reduktionsfaktorer, LENI-tal'!$Q$12,INDEX('4. Reduktionsfaktorer, LENI-tal'!$H$13:$O$23,MATCH(R$27,'4. Reduktionsfaktorer, LENI-tal'!$H$13:$H$23,0),4), R$25="SKOLA OCH RESTAURANG",INDEX('4. Reduktionsfaktorer, LENI-tal'!$H$24:$O$32,MATCH(R$27,'4. Reduktionsfaktorer, LENI-tal'!$H$24:$H$32,0),4), R$25='4. Reduktionsfaktorer, LENI-tal'!$S$12,INDEX('4. Reduktionsfaktorer, LENI-tal'!$H$33:$O$37,MATCH(R$27,'4. Reduktionsfaktorer, LENI-tal'!$H$33:$H$37,0),4), R$25='4. Reduktionsfaktorer, LENI-tal'!$T$12,INDEX('4. Reduktionsfaktorer, LENI-tal'!$H$38:$O$45,MATCH(R$27,'4. Reduktionsfaktorer, LENI-tal'!$H$38:$H$45,0),4)), "Fyll i byggnads- och rumstyp ovan")} -> Fyll i byggnads- och rumstyp ovan
B39: 2.8 | C39: Reduktionsfaktor dagsljusstyrning | I39: {=IFERROR(_xlfn.IFS(I$25='4. Reduktionsfaktorer, LENI-tal'!$Q$12,INDEX('4. Reduktionsfaktorer, LENI-tal'!$H$13:$O$23,MATCH(I$27,'4. Reduktionsfaktorer, LENI-tal'!$H$13:$H$23,0),5), I$25="SKOLA OCH RESTAURANG",INDEX('4. Reduktionsfaktorer, LENI-tal'!$H$24:$O$32,MATCH(I$27,'4. Reduktionsfaktorer, LENI-tal'!$H$24:$H$32,0),5), I$25='4. Reduktionsfaktorer, LENI-tal'!$S$12,INDEX('4. Reduktionsfaktorer, LENI-tal'!$H$33:$O$37,MATCH(I$27,'4. Reduktionsfaktorer, LENI-tal'!$H$33:$H$37,0),5), I$25='4. Reduktionsfaktorer, LENI-tal'!$T$12,INDEX('4. Reduktionsfaktorer, LENI-tal'!$H$38:$O$45,MATCH(I$27,'4. Reduktionsfaktorer, LENI-tal'!$H$38:$H$45,0),5)), "Fyll i byggnads- och rumstyp ovan")} -> Fyll i byggnads- och rumstyp ovan | J39: {=IFERROR(_xlfn.IFS(J$25='4. Reduktionsfaktorer, LENI-tal'!$Q$12,INDEX('4. Reduktionsfaktorer, LENI-tal'!$H$13:$O$23,MATCH(J$27,'4. Reduktionsfaktorer, LENI-tal'!$H$13:$H$23,0),5), J$25="SKOLA OCH RESTAURANG",INDEX('4. Reduktionsfaktorer, LENI-tal'!$H$24:$O$32,MATCH(J$27,'4. Reduktionsfaktorer, LENI-tal'!$H$24:$H$32,0),5), J$25='4. Reduktionsfaktorer, LENI-tal'!$S$12,INDEX('4. Reduktionsfaktorer, LENI-tal'!$H$33:$O$37,MATCH(J$27,'4. Reduktionsfaktorer, LENI-tal'!$H$33:$H$37,0),5), J$25='4. Reduktionsfaktorer, LENI-tal'!$T$12,INDEX('4. Reduktionsfaktorer, LENI-tal'!$H$38:$O$45,MATCH(J$27,'4. Reduktionsfaktorer, LENI-tal'!$H$38:$H$45,0),5)), "Fyll i byggnads- och rumstyp ovan")} -> Fyll i byggnads- och rumstyp ovan | K39: {=IFERROR(_xlfn.IFS(K$25='4. Reduktionsfaktorer, LENI-tal'!$Q$12,INDEX('4. Reduktionsfaktorer, LENI-tal'!$H$13:$O$23,MATCH(K$27,'4. Reduktionsfaktorer, LENI-tal'!$H$13:$H$23,0),5), K$25="SKOLA OCH RESTAURANG",INDEX('4. Reduktionsfaktorer, LENI-tal'!$H$24:$O$32,MATCH(K$27,'4. Reduktionsfaktorer, LENI-tal'!$H$24:$H$32,0),5), K$25='4. Reduktionsfaktorer, LENI-tal'!$S$12,INDEX('4. Reduktionsfaktorer, LENI-tal'!$H$33:$O$37,MATCH(K$27,'4. Reduktionsfaktorer, LENI-tal'!$H$33:$H$37,0),5), K$25='4. Reduktionsfaktorer, LENI-tal'!$T$12,INDEX('4. Reduktionsfaktorer, LENI-tal'!$H$38:$O$45,MATCH(K$27,'4. Reduktionsfaktorer, LENI-tal'!$H$38:$H$45,0),5)), "Fyll i byggnads- och rumstyp ovan")} -> Fyll i byggnads- och rumstyp ovan | L39: {=IFERROR(_xlfn.IFS(L$25='4. Reduktionsfaktorer, LENI-tal'!$Q$12,INDEX('4. Reduktionsfaktorer, LENI-tal'!$H$13:$O$23,MATCH(L$27,'4. Reduktionsfaktorer, LENI-tal'!$H$13:$H$23,0),5), L$25="SKOLA OCH RESTAURANG",INDEX('4. Reduktionsfaktorer, LENI-tal'!$H$24:$O$32,MATCH(L$27,'4. Reduktionsfaktorer, LENI-tal'!$H$24:$H$32,0),5), L$25='4. Reduktionsfaktorer, LENI-tal'!$S$12,INDEX('4. Reduktionsfaktorer, LENI-tal'!$H$33:$O$37,MATCH(L$27,'4. Reduktionsfaktorer, LENI-tal'!$H$33:$H$37,0),5), L$25='4. Reduktionsfaktorer, LENI-tal'!$T$12,INDEX('4. Reduktionsfaktorer, LENI-tal'!$H$38:$O$45,MATCH(L$27,'4. Reduktionsfaktorer, LENI-tal'!$H$38:$H$45,0),5)), "Fyll i byggnads- och rumstyp ovan")} -> Fyll i byggnads- och rumstyp ovan | M39: {=IFERROR(_xlfn.IFS(M$25='4. Reduktionsfaktorer, LENI-tal'!$Q$12,INDEX('4. Reduktionsfaktorer, LENI-tal'!$H$13:$O$23,MATCH(M$27,'4. Reduktionsfaktorer, LENI-tal'!$H$13:$H$23,0),5), M$25="SKOLA OCH RESTAURANG",INDEX('4. Reduktionsfaktorer, LENI-tal'!$H$24:$O$32,MATCH(M$27,'4. Reduktionsfaktorer, LENI-tal'!$H$24:$H$32,0),5), M$25='4. Reduktionsfaktorer, LENI-tal'!$S$12,INDEX('4. Reduktionsfaktorer, LENI-tal'!$H$33:$O$37,MATCH(M$27,'4. Reduktionsfaktorer, LENI-tal'!$H$33:$H$37,0),5), M$25='4. Reduktionsfaktorer, LENI-tal'!$T$12,INDEX('4. Reduktionsfaktorer, LENI-tal'!$H$38:$O$45,MATCH(M$27,'4. Reduktionsfaktorer, LENI-tal'!$H$38:$H$45,0),5)), "Fyll i byggnads- och rumstyp ovan")} -> Fyll i byggnads- och rumstyp ovan | N39: {=IFERROR(_xlfn.IFS(N$25='4. Reduktionsfaktorer, LENI-tal'!$Q$12,INDEX('4. Reduktionsfaktorer, LENI-tal'!$H$13:$O$23,MATCH(N$27,'4. Reduktionsfaktorer, LENI-tal'!$H$13:$H$23,0),5), N$25="SKOLA OCH RESTAURANG",INDEX('4. Reduktionsfaktorer, LENI-tal'!$H$24:$O$32,MATCH(N$27,'4. Reduktionsfaktorer, LENI-tal'!$H$24:$H$32,0),5), N$25='4. Reduktionsfaktorer, LENI-tal'!$S$12,INDEX('4. Reduktionsfaktorer, LENI-tal'!$H$33:$O$37,MATCH(N$27,'4. Reduktionsfaktorer, LENI-tal'!$H$33:$H$37,0),5), N$25='4. Reduktionsfaktorer, LENI-tal'!$T$12,INDEX('4. Reduktionsfaktorer, LENI-tal'!$H$38:$O$45,MATCH(N$27,'4. Reduktionsfaktorer, LENI-tal'!$H$38:$H$45,0),5)), "Fyll i byggnads- och rumstyp ovan")} -> Fyll i byggnads- och rumstyp ovan | O39: {=IFERROR(_xlfn.IFS(O$25='4. Reduktionsfaktorer, LENI-tal'!$Q$12,INDEX('4. Reduktionsfaktorer, LENI-tal'!$H$13:$O$23,MATCH(O$27,'4. Reduktionsfaktorer, LENI-tal'!$H$13:$H$23,0),5), O$25="SKOLA OCH RESTAURANG",INDEX('4. Reduktionsfaktorer, LENI-tal'!$H$24:$O$32,MATCH(O$27,'4. Reduktionsfaktorer, LENI-tal'!$H$24:$H$32,0),5), O$25='4. Reduktionsfaktorer, LENI-tal'!$S$12,INDEX('4. Reduktionsfaktorer, LENI-tal'!$H$33:$O$37,MATCH(O$27,'4. Reduktionsfaktorer, LENI-tal'!$H$33:$H$37,0),5), O$25='4. Reduktionsfaktorer, LENI-tal'!$T$12,INDEX('4. Reduktionsfaktorer, LENI-tal'!$H$38:$O$45,MATCH(O$27,'4. Reduktionsfaktorer, LENI-tal'!$H$38:$H$45,0),5)), "Fyll i byggnads- och rumstyp ovan")} -> Fyll i byggnads- och rumstyp ovan | P39: {=IFERROR(_xlfn.IFS(P$25='4. Reduktionsfaktorer, LENI-tal'!$Q$12,INDEX('4. Reduktionsfaktorer, LENI-tal'!$H$13:$O$23,MATCH(P$27,'4. Reduktionsfaktorer, LENI-tal'!$H$13:$H$23,0),5), P$25="SKOLA OCH RESTAURANG",INDEX('4. Reduktionsfaktorer, LENI-tal'!$H$24:$O$32,MATCH(P$27,'4. Reduktionsfaktorer, LENI-tal'!$H$24:$H$32,0),5), P$25='4. Reduktionsfaktorer, LENI-tal'!$S$12,INDEX('4. Reduktionsfaktorer, LENI-tal'!$H$33:$O$37,MATCH(P$27,'4. Reduktionsfaktorer, LENI-tal'!$H$33:$H$37,0),5), P$25='4. Reduktionsfaktorer, LENI-tal'!$T$12,INDEX('4. Reduktionsfaktorer, LENI-tal'!$H$38:$O$45,MATCH(P$27,'4. Reduktionsfaktorer, LENI-tal'!$H$38:$H$45,0),5)), "Fyll i byggnads- och rumstyp ovan")} -> Fyll i byggnads- och rumstyp ovan | ... R39: {=IFERROR(_xlfn.IFS(R$25='4. Reduktionsfaktorer, LENI-tal'!$Q$12,INDEX('4. Reduktionsfaktorer, LENI-tal'!$H$13:$O$23,MATCH(R$27,'4. Reduktionsfaktorer, LENI-tal'!$H$13:$H$23,0),5), R$25="SKOLA OCH RESTAURANG",INDEX('4. Reduktionsfaktorer, LENI-tal'!$H$24:$O$32,MATCH(R$27,'4. Reduktionsfaktorer, LENI-tal'!$H$24:$H$32,0),5), R$25='4. Reduktionsfaktorer, LENI-tal'!$S$12,INDEX('4. Reduktionsfaktorer, LENI-tal'!$H$33:$O$37,MATCH(R$27,'4. Reduktionsfaktorer, LENI-tal'!$H$33:$H$37,0),5), R$25='4. Reduktionsfaktorer, LENI-tal'!$T$12,INDEX('4. Reduktionsfaktorer, LENI-tal'!$H$38:$O$45,MATCH(R$27,'4. Reduktionsfaktorer, LENI-tal'!$H$38:$H$45,0),5)), "Fyll i byggnads- och rumstyp ovan")} -> Fyll i byggnads- och rumstyp ovan
B40: 2.9 | C40: Total reduktionsfaktor för styrning | I40: =IF(IF(I36=$I$238,I37,IF(I36=$I$239,I37*I38,IF(I36=$I$240,I37*I38*I39,1)))=0,"Fyll i 2.6-2.8",IF(I36=$I$238,I37,IF(I36=$I$239,I37*I38,IF(I36=$I$240,I37*I38*I39,1)))) -> 1 | J40: =IF(IF(J36=$I$238,J37,IF(J36=$I$239,J37*J38,IF(J36=$I$240,J37*J38*J39,1)))=0,"Fyll i 2.6-2.8",IF(J36=$I$238,J37,IF(J36=$I$239,J37*J38,IF(J36=$I$240,J37*J38*J39,1)))) -> 1 | K40: =IF(IF(K36=$I$238,K37,IF(K36=$I$239,K37*K38,IF(K36=$I$240,K37*K38*K39,1)))=0,"Fyll i 2.6-2.8",IF(K36=$I$238,K37,IF(K36=$I$239,K37*K38,IF(K36=$I$240,K37*K38*K39,1)))) -> 1 | L40: =IF(IF(L36=$I$238,L37,IF(L36=$I$239,L37*L38,IF(L36=$I$240,L37*L38*L39,1)))=0,"Fyll i 2.6-2.8",IF(L36=$I$238,L37,IF(L36=$I$239,L37*L38,IF(L36=$I$240,L37*L38*L39,1)))) -> 1 | M40: =IF(IF(M36=$I$238,M37,IF(M36=$I$239,M37*M38,IF(M36=$I$240,M37*M38*M39,1)))=0,"Fyll i 2.6-2.8",IF(M36=$I$238,M37,IF(M36=$I$239,M37*M38,IF(M36=$I$240,M37*M38*M39,1)))) -> 1 | N40: =IF(IF(N36=$I$238,N37,IF(N36=$I$239,N37*N38,IF(N36=$I$240,N37*N38*N39,1)))=0,"Fyll i 2.6-2.8",IF(N36=$I$238,N37,IF(N36=$I$239,N37*N38,IF(N36=$I$240,N37*N38*N39,1)))) -> 1 | O40: =IF(IF(O36=$I$238,O37,IF(O36=$I$239,O37*O38,IF(O36=$I$240,O37*O38*O39,1)))=0,"Fyll i 2.6-2.8",IF(O36=$I$238,O37,IF(O36=$I$239,O37*O38,IF(O36=$I$240,O37*O38*O39,1)))) -> 1 | P40: =IF(IF(P36=$I$238,P37,IF(P36=$I$239,P37*P38,IF(P36=$I$240,P37*P38*P39,1)))=0,"Fyll i 2.6-2.8",IF(P36=$I$238,P37,IF(P36=$I$239,P37*P38,IF(P36=$I$240,P37*P38*P39,1)))) -> 1 | ... R40: =IF(IF(R36=$I$238,R37,IF(R36=$I$239,R37*R38,IF(R36=$I$240,R37*R38*R39,1)))=0,"Fyll i 2.6-2.8",IF(R36=$I$238,R37,IF(R36=$I$239,R37*R38,IF(R36=$I$240,R37*R38*R39,1)))) -> 1
B41: 2.10 | C41: Underhållskostnader | H41: kr/år
C43: ARMATURTYP 2
B44: 2.1 | C44: Antal armaturer | H44: stk
B45: 2.2 | C45: Armaturpris | H45: kr/stk
B46: 2.3 | C46: Material- och arbetskostnader armatur | H46: kr/stk
B47: 2.4 | C47: Effekt per armatur, inkl. driftsförluster | H47: W/stk
...

Sheet 2. LCC A2
A1: (PW: LCC)
G2: LCC-kalkyl för upphandling av inomhusbelysning
G3: ='1. Introduktion'!G3 -> Version 3.0
G4: ='1. Introduktion'!G4 -> Datum: 2024-12-17
C8: LCC-kalkyl Anläggning alternativ 2
C10: Kalkylförutsättningar (anges av beställaren) | K10: Byggnadstyp | L10: 0
C11: PROJEKT: | F11: Projektnamn | K11: Kontor | L11: 2500
C12: DATUM: | F12: ÅÅÅÅ-MM-DD | K12: Skola, restaurang | L12: 2000
C13: HANDLÄGGARE: | F13: Namn | K13: Sporthall | L13: 4000
K14: Vård | L14: 5000
B15: 1.1 | C15: Tid kalkylen omfattar | I15: år
B16: 1.2 | C16: Kalkylränta | H16: 0.05 | K16: Indata till fält 16: Byggnadens driftitid h/ år
B17: 1.3 | C17: Elpris | I17: kr/kWh | K17: Byggnadstyp | L17: Byggnadstyp
B18: 1.4 | C18: Årlig prisförändring energi (frivillig) | K18: Eget värde för drifttid h/år
B19: 1.5 | C19: Klimatpåverkan energianvändning (frivillig) | I19: kgCO2/kwh | K19: Driftitd timmar per år | L19: =IF(ISBLANK($L$18),VLOOKUP($L$17,$K$10:$L$14,2),$L$18) -> 0
B20: 1.6 | C20: Drifttid | H20: =$L$19 -> 0 | I20: h/år
C22: Beskrivning av anläggningen och belysningsförslag
C24: BESKRIVNING AV ANLÄGGNINGEN (anges av beställaren)
C25: Byggnadstyp | I25: Byggnadstyp 1 | J25: Byggnadstyp 2 | K25: Byggnadstyp 3 | L25: Byggnadstyp 4 | M25: Byggnadstyp 5 | N25: Byggnadstyp 6 | O25: Byggnadstyp 7 | P25: Byggnadstyp 8 | Q25: Byggnadstyp 9 | R25: Byggnadstyp 10
C26: Byggnadstyp hjälprad | I26: =SUBSTITUTE(I25," ","_") -> Byggnadstyp_1 | J26: =SUBSTITUTE(J25," ","_") -> Byggnadstyp_2 | K26: =SUBSTITUTE(K25," ","_") -> Byggnadstyp_3 | L26: =SUBSTITUTE(L25," ","_") -> Byggnadstyp_4 | M26: =SUBSTITUTE(M25," ","_") -> Byggnadstyp_5 | N26: =SUBSTITUTE(N25," ","_") -> Byggnadstyp_6 | O26: =SUBSTITUTE(O25," ","_") -> Byggnadstyp_7 | P26: =SUBSTITUTE(P25," ","_") -> Byggnadstyp_8 | ... R26: =SUBSTITUTE(R25," ","_") -> Byggnadstyp_10
C27: Rumstyp (välj byggnadstyp ovan för att få lista med giltiga rumstyper) | I27: Rumstyp 1 | J27: Rumstyp 2 | K27: Rumstyp 3 | L27: Rumstyp 4 | M27: Rumstyp 5 | N27: Rumstyp 6 | O27: Rumstyp 7 | P27: Rumstyp 8 | Q27: Rumstyp 9 | R27: Rumstyp 10
C28: Antal rum av samma typ | H28: stk | I28: 1 | J28: 1 | K28: 1 | L28: 1 | M28: 1 | N28: 1 | O28: 1 | P28: 1 | Q28: 1 | R28: 1
C29: Antal kvadratmeter | H29: m2/rum | I29: 1 | J29: 1 | K29: 1 | L29: 1 | M29: 1 | N29: 1 | O29: 1 | P29: 1 | Q29: 1 | R29: 1
C30: BELYSNINGSFÖRSLAG (anges av anbudsgivaren)
C31: ARMATURTYP 1
B32: 2.1 | C32: Antal armaturer | H32: stk
B33: 2.2 | C33: Armaturpris | H33: kr/stk
B34: 2.3 | C34: Material- och arbetskostnader armatur | H34: kr/stk
B35: 2.4 | C35: Effekt per armatur, inkl. driftsförluster | H35: W/stk
B36: 2.5 | C36: Typ av styrning | I36: Ingen | J36: Ingen | K36: Ingen | L36: Ingen | M36: Ingen | N36: Ingen | O36: Ingen | P36: Ingen | Q36: Ingen | R36: Ingen
B37: 2.6 | C37: Reduktionsfaktor manuell styrning | I37: {=IFERROR(_xlfn.IFS(I$25='4. Reduktionsfaktorer, LENI-tal'!$Q$12,INDEX('4. Reduktionsfaktorer, LENI-tal'!$H$13:$O$23,MATCH(I$27,'4. Reduktionsfaktorer, LENI-tal'!$H$13:$H$23,0),3), I$25="SKOLA OCH RESTAURANG",INDEX('4. Reduktionsfaktorer, LENI-tal'!$H$24:$O$32,MATCH(I$27,'4. Reduktionsfaktorer, LENI-tal'!$H$24:$H$32,0),3), I$25='4. Reduktionsfaktorer, LENI-tal'!$S$12,INDEX('4. Reduktionsfaktorer, LENI-tal'!$H$33:$O$37,MATCH(I$27,'4. Reduktionsfaktorer, LENI-tal'!$H$33:$H$37,0),3), I$25='4. Reduktionsfaktorer, LENI-tal'!$T$12,INDEX('4. Reduktionsfaktorer, LENI-tal'!$H$38:$O$45,MATCH(I$27,'4. Reduktionsfaktorer, LENI-tal'!$H$38:$H$45,0),3)), "Fyll i byggnads- och rumstyp ovan")} -> Fyll i byggnads- och rumstyp ovan | J37: {=IFERROR(_xlfn.IFS(J$25='4. Reduktionsfaktorer, LENI-tal'!$Q$12,INDEX('4. Reduktionsfaktorer, LENI-tal'!$H$13:$O$23,MATCH(J$27,'4. Reduktionsfaktorer, LENI-tal'!$H$13:$H$23,0),3), J$25="SKOLA OCH RESTAURANG",INDEX('4. Reduktionsfaktorer, LENI-tal'!$H$24:$O$32,MATCH(J$27,'4. Reduktionsfaktorer, LENI-tal'!$H$24:$H$32,0),3), J$25='4. Reduktionsfaktorer, LENI-tal'!$S$12,INDEX('4. Reduktionsfaktorer, LENI-tal'!$H$33:$O$37,MATCH(J$27,'4. Reduktionsfaktorer, LENI-tal'!$H$33:$H$37,0),3), J$25='4. Reduktionsfaktorer, LENI-tal'!$T$12,INDEX('4. Reduktionsfaktorer, LENI-tal'!$H$38:$O$45,MATCH(J$27,'4. Reduktionsfaktorer, LENI-tal'!$H$38:$H$45,0),3)), "Fyll i byggnads- och rumstyp ovan")} -> Fyll i byggnads- och rumstyp ovan | K37: {=IFERROR(_xlfn.IFS(K$25='4. Reduktionsfaktorer, LENI-tal'!$Q$12,INDEX('4. Reduktionsfaktorer, LENI-tal'!$H$13:$O$23,MATCH(K$27,'4. Reduktionsfaktorer, LENI-tal'!$H$13:$H$23,0),3), K$25="SKOLA OCH RESTAURANG",INDEX('4. Reduktionsfaktorer, LENI-tal'!$H$24:$O$32,MATCH(K$27,'4. Reduktionsfaktorer, LENI-tal'!$H$24:$H$32,0),3), K$25='4. Reduktionsfaktorer, LENI-tal'!$S$12,INDEX('4. Reduktionsfaktorer, LENI-tal'!$H$33:$O$37,MATCH(K$27,'4. Reduktionsfaktorer, LENI-tal'!$H$33:$H$37,0),3), K$25='4. Reduktionsfaktorer, LENI-tal'!$T$12,INDEX('4. Reduktionsfaktorer, LENI-tal'!$H$38:$O$45,MATCH(K$27,'4. Reduktionsfaktorer, LENI-tal'!$H$38:$H$45,0),3)), "Fyll i byggnads- och rumstyp ovan")} -> Fyll i byggnads- och rumstyp ovan | L37: {=IFERROR(_xlfn.IFS(L$25='4. Reduktionsfaktorer, LENI-tal'!$Q$12,INDEX('4. Reduktionsfaktorer, LENI-tal'!$H$13:$O$23,MATCH(L$27,'4. Reduktionsfaktorer, LENI-tal'!$H$13:$H$23,0),3), L$25="SKOLA OCH RESTAURANG",INDEX('4. Reduktionsfaktorer, LENI-tal'!$H$24:$O$32,MATCH(L$27,'4. Reduktionsfaktorer, LENI-tal'!$H$24:$H$32,0),3), L$25='4. Reduktionsfaktorer, LENI-tal'!$S$12,INDEX('4. Reduktionsfaktorer, LENI-tal'!$H$33:$O$37,MATCH(L$27,'4. Reduktionsfaktorer, LENI-tal'!$H$33:$H$37,0),3), L$25='4. Reduktionsfaktorer, LENI-tal'!$T$12,INDEX('4. Reduktionsfaktorer, LENI-tal'!$H$38:$O$45,MATCH(L$27,'4. Reduktionsfaktorer, LENI-tal'!$H$38:$H$45,0),3)), "Fyll i byggnads- och rumstyp ovan")} -> Fyll i byggnads- och rumstyp ovan | M37: {=IFERROR(_xlfn.IFS(M$25='4. Reduktionsfaktorer, LENI-tal'!$Q$12,INDEX('4. Reduktionsfaktorer, LENI-tal'!$H$13:$O$23,MATCH(M$27,'4. Reduktionsfaktorer, LENI-tal'!$H$13:$H$23,0),3), M$25="SKOLA OCH RESTAURANG",INDEX('4. Reduktionsfaktorer, LENI-tal'!$H$24:$O$32,MATCH(M$27,'4. Reduktionsfaktorer, LENI-tal'!$H$24:$H$32,0),3), M$25='4. Reduktionsfaktorer, LENI-tal'!$S$12,INDEX('4. Reduktionsfaktorer, LENI-tal'!$H$33:$O$37,MATCH(M$27,'4. Reduktionsfaktorer, LENI-tal'!$H$33:$H$37,0),3), M$25='4. Reduktionsfaktorer, LENI-tal'!$T$12,INDEX('4. Reduktionsfaktorer, LENI-tal'!$H$38:$O$45,MATCH(M$27,'4. Reduktionsfaktorer, LENI-tal'!$H$38:$H$45,0),3)), "Fyll i byggnads- och rumstyp ovan")} -> Fyll i byggnads- och rumstyp ovan | N37: {=IFERROR(_xlfn.IFS(N$25='4. Reduktionsfaktorer, LENI-tal'!$Q$12,INDEX('4. Reduktionsfaktorer, LENI-tal'!$H$13:$O$23,MATCH(N$27,'4. Reduktionsfaktorer, LENI-tal'!$H$13:$H$23,0),3), N$25="SKOLA OCH RESTAURANG",INDEX('4. Reduktionsfaktorer, LENI-tal'!$H$24:$O$32,MATCH(N$27,'4. Reduktionsfaktorer, LENI-tal'!$H$24:$H$32,0),3), N$25='4. Reduktionsfaktorer, LENI-tal'!$S$12,INDEX('4. Reduktionsfaktorer, LENI-tal'!$H$33:$O$37,MATCH(N$27,'4. Reduktionsfaktorer, LENI-tal'!$H$33:$H$37,0),3), N$25='4. Reduktionsfaktorer, LENI-tal'!$T$12,INDEX('4. Reduktionsfaktorer, LENI-tal'!$H$38:$O$45,MATCH(N$27,'4. Reduktionsfaktorer, LENI-tal'!$H$38:$H$45,0),3)), "Fyll i byggnads- och rumstyp ovan")} -> Fyll i byggnads- och rumstyp ovan | O37: {=IFERROR(_xlfn.IFS(O$25='4. Reduktionsfaktorer, LENI-tal'!$Q$12,INDEX('4. Reduktionsfaktorer, LENI-tal'!$H$13:$O$23,MATCH(O$27,'4. Reduktionsfaktorer, LENI-tal'!$H$13:$H$23,0),3), O$25="SKOLA OCH RESTAURANG",INDEX('4. Reduktionsfaktorer, LENI-tal'!$H$24:$O$32,MATCH(O$27,'4. Reduktionsfaktorer, LENI-tal'!$H$24:$H$32,0),3), O$25='4. Reduktionsfaktorer, LENI-tal'!$S$12,INDEX('4. Reduktionsfaktorer, LENI-tal'!$H$33:$O$37,MATCH(O$27,'4. Reduktionsfaktorer, LENI-tal'!$H$33:$H$37,0),3), O$25='4. Reduktionsfaktorer, LENI-tal'!$T$12,INDEX('4. Reduktionsfaktorer, LENI-tal'!$H$38:$O$45,MATCH(O$27,'4. Reduktionsfaktorer, LENI-tal'!$H$38:$H$45,0),3)), "Fyll i byggnads- och rumstyp ovan")} -> Fyll i byggnads- och rumstyp ovan | P37: {=IFERROR(_xlfn.IFS(P$25='4. Reduktionsfaktorer, LENI-tal'!$Q$12,INDEX('4. Reduktionsfaktorer, LENI-tal'!$H$13:$O$23,MATCH(P$27,'4. Reduktionsfaktorer, LENI-tal'!$H$13:$H$23,0),3), P$25="SKOLA OCH RESTAURANG",INDEX('4. Reduktionsfaktorer, LENI-tal'!$H$24:$O$32,MATCH(P$27,'4. Reduktionsfaktorer, LENI-tal'!$H$24:$H$32,0),3), P$25='4. Reduktionsfaktorer, LENI-tal'!$S$12,INDEX('4. Reduktionsfaktorer, LENI-tal'!$H$33:$O$37,MATCH(P$27,'4. Reduktionsfaktorer, LENI-tal'!$H$33:$H$37,0),3), P$25='4. Reduktionsfaktorer, LENI-tal'!$T$12,INDEX('4. Reduktionsfaktorer, LENI-tal'!$H$38:$O$45,MATCH(P$27,'4. Reduktionsfaktorer, LENI-tal'!$H$38:$H$45,0),3)), "Fyll i byggnads- och rumstyp ovan")} -> Fyll i byggnads- och rumstyp ovan | ... R37: {=IFERROR(_xlfn.IFS(R$25='4. Reduktionsfaktorer, LENI-tal'!$Q$12,INDEX('4. Reduktionsfaktorer, LENI-tal'!$H$13:$O$23,MATCH(R$27,'4. Reduktionsfaktorer, LENI-tal'!$H$13:$H$23,0),3), R$25="SKOLA OCH RESTAURANG",INDEX('4. Reduktionsfaktorer, LENI-tal'!$H$24:$O$32,MATCH(R$27,'4. Reduktionsfaktorer, LENI-tal'!$H$24:$H$32,0),3), R$25='4. Reduktionsfaktorer, LENI-tal'!$S$12,INDEX('4. Reduktionsfaktorer, LENI-tal'!$H$33:$O$37,MATCH(R$27,'4. Reduktionsfaktorer, LENI-tal'!$H$33:$H$37,0),3), R$25='4. Reduktionsfaktorer, LENI-tal'!$T$12,INDEX('4. Reduktionsfaktorer, LENI-tal'!$H$38:$O$45,MATCH(R$27,'4. Reduktionsfaktorer, LENI-tal'!$H$38:$H$45,0),3)), "Fyll i byggnads- och rumstyp ovan")} -> Fyll i byggnads- och rumstyp ovan
B38: 2.7 | C38: Reduktionsfaktor närvaro-/frånvarostyrning | I38: {=IFERROR(_xlfn.IFS(I$25='4. Reduktionsfaktorer, LENI-tal'!$Q$12,INDEX('4. Reduktionsfaktorer, LENI-tal'!$H$13:$O$23,MATCH(I$27,'4. Reduktionsfaktorer, LENI-tal'!$H$13:$H$23,0),4), I$25="SKOLA OCH RESTAURANG",INDEX('4. Reduktionsfaktorer, LENI-tal'!$H$24:$O$32,MATCH(I$27,'4. Reduktionsfaktorer, LENI-tal'!$H$24:$H$32,0),4), I$25='4. Reduktionsfaktorer, LENI-tal'!$S$12,INDEX('4. Reduktionsfaktorer, LENI-tal'!$H$33:$O$37,MATCH(I$27,'4. Reduktionsfaktorer, LENI-tal'!$H$33:$H$37,0),4), I$25='4. Reduktionsfaktorer, LENI-tal'!$T$12,INDEX('4. Reduktionsfaktorer, LENI-tal'!$H$38:$O$45,MATCH(I$27,'4. Reduktionsfaktorer, LENI-tal'!$H$38:$H$45,0),4)), "Fyll i byggnads- och rumstyp ovan")} -> Fyll i byggnads- och rumstyp ovan | J38: {=IFERROR(_xlfn.IFS(J$25='4. Reduktionsfaktorer, LENI-tal'!$Q$12,INDEX('4. Reduktionsfaktorer, LENI-tal'!$H$13:$O$23,MATCH(J$27,'4. Reduktionsfaktorer, LENI-tal'!$H$13:$H$23,0),4), J$25="SKOLA OCH RESTAURANG",INDEX('4. Reduktionsfaktorer, LENI-tal'!$H$24:$O$32,MATCH(J$27,'4. Reduktionsfaktorer, LENI-tal'!$H$24:$H$32,0),4), J$25='4. Reduktionsfaktorer, LENI-tal'!$S$12,INDEX('4. Reduktionsfaktorer, LENI-tal'!$H$33:$O$37,MATCH(J$27,'4. Reduktionsfaktorer, LENI-tal'!$H$33:$H$37,0),4), J$25='4. Reduktionsfaktorer, LENI-tal'!$T$12,INDEX('4. Reduktionsfaktorer, LENI-tal'!$H$38:$O$45,MATCH(J$27,'4. Reduktionsfaktorer, LENI-tal'!$H$38:$H$45,0),4)), "Fyll i byggnads- och rumstyp ovan")} -> Fyll i byggnads- och rumstyp ovan | K38: {=IFERROR(_xlfn.IFS(K$25='4. Reduktionsfaktorer, LENI-tal'!$Q$12,INDEX('4. Reduktionsfaktorer, LENI-tal'!$H$13:$O$23,MATCH(K$27,'4. Reduktionsfaktorer, LENI-tal'!$H$13:$H$23,0),4), K$25="SKOLA OCH RESTAURANG",INDEX('4. Reduktionsfaktorer, LENI-tal'!$H$24:$O$32,MATCH(K$27,'4. Reduktionsfaktorer, LENI-tal'!$H$24:$H$32,0),4), K$25='4. Reduktionsfaktorer, LENI-tal'!$S$12,INDEX('4. Reduktionsfaktorer, LENI-tal'!$H$33:$O$37,MATCH(K$27,'4. Reduktionsfaktorer, LENI-tal'!$H$33:$H$37,0),4), K$25='4. Reduktionsfaktorer, LENI-tal'!$T$12,INDEX('4. Reduktionsfaktorer, LENI-tal'!$H$38:$O$45,MATCH(K$27,'4. Reduktionsfaktorer, LENI-tal'!$H$38:$H$45,0),4)), "Fyll i byggnads- och rumstyp ovan")} -> Fyll i byggnads- och rumstyp ovan | L38: {=IFERROR(_xlfn.IFS(L$25='4. Reduktionsfaktorer, LENI-tal'!$Q$12,INDEX('4. Reduktionsfaktorer, LENI-tal'!$H$13:$O$23,MATCH(L$27,'4. Reduktionsfaktorer, LENI-tal'!$H$13:$H$23,0),4), L$25="SKOLA OCH RESTAURANG",INDEX('4. Reduktionsfaktorer, LENI-tal'!$H$24:$O$32,MATCH(L$27,'4. Reduktionsfaktorer, LENI-tal'!$H$24:$H$32,0),4), L$25='4. Reduktionsfaktorer, LENI-tal'!$S$12,INDEX('4. Reduktionsfaktorer, LENI-tal'!$H$33:$O$37,MATCH(L$27,'4. Reduktionsfaktorer, LENI-tal'!$H$33:$H$37,0),4), L$25='4. Reduktionsfaktorer, LENI-tal'!$T$12,INDEX('4. Reduktionsfaktorer, LENI-tal'!$H$38:$O$45,MATCH(L$27,'4. Reduktionsfaktorer, LENI-tal'!$H$38:$H$45,0),4)), "Fyll i byggnads- och rumstyp ovan")} -> Fyll i byggnads- och rumstyp ovan | M38: {=IFERROR(_xlfn.IFS(M$25='4. Reduktionsfaktorer, LENI-tal'!$Q$12,INDEX('4. Reduktionsfaktorer, LENI-tal'!$H$13:$O$23,MATCH(M$27,'4. Reduktionsfaktorer, LENI-tal'!$H$13:$H$23,0),4), M$25="SKOLA OCH RESTAURANG",INDEX('4. Reduktionsfaktorer, LENI-tal'!$H$24:$O$32,MATCH(M$27,'4. Reduktionsfaktorer, LENI-tal'!$H$24:$H$32,0),4), M$25='4. Reduktionsfaktorer, LENI-tal'!$S$12,INDEX('4. Reduktionsfaktorer, LENI-tal'!$H$33:$O$37,MATCH(M$27,'4. Reduktionsfaktorer, LENI-tal'!$H$33:$H$37,0),4), M$25='4. Reduktionsfaktorer, LENI-tal'!$T$12,INDEX('4. Reduktionsfaktorer, LENI-tal'!$H$38:$O$45,MATCH(M$27,'4. Reduktionsfaktorer, LENI-tal'!$H$38:$H$45,0),4)), "Fyll i byggnads- och rumstyp ovan")} -> Fyll i byggnads- och rumstyp ovan | N38: {=IFERROR(_xlfn.IFS(N$25='4. Reduktionsfaktorer, LENI-tal'!$Q$12,INDEX('4. Reduktionsfaktorer, LENI-tal'!$H$13:$O$23,MATCH(N$27,'4. Reduktionsfaktorer, LENI-tal'!$H$13:$H$23,0),4), N$25="SKOLA OCH RESTAURANG",INDEX('4. Reduktionsfaktorer, LENI-tal'!$H$24:$O$32,MATCH(N$27,'4. Reduktionsfaktorer, LENI-tal'!$H$24:$H$32,0),4), N$25='4. Reduktionsfaktorer, LENI-tal'!$S$12,INDEX('4. Reduktionsfaktorer, LENI-tal'!$H$33:$O$37,MATCH(N$27,'4. Reduktionsfaktorer, LENI-tal'!$H$33:$H$37,0),4), N$25='4. Reduktionsfaktorer, LENI-tal'!$T$12,INDEX('4. Reduktionsfaktorer, LENI-tal'!$H$38:$O$45,MATCH(N$27,'4. Reduktionsfaktorer, LENI-tal'!$H$38:$H$45,0),4)), "Fyll i byggnads- och rumstyp ovan")} -> Fyll i byggnads- och rumstyp ovan | O38: {=IFERROR(_xlfn.IFS(O$25='4. Reduktionsfaktorer, LENI-tal'!$Q$12,INDEX('4. Reduktionsfaktorer, LENI-tal'!$H$13:$O$23,MATCH(O$27,'4. Reduktionsfaktorer, LENI-tal'!$H$13:$H$23,0),4), O$25="SKOLA OCH RESTAURANG",INDEX('4. Reduktionsfaktorer, LENI-tal'!$H$24:$O$32,MATCH(O$27,'4. Reduktionsfaktorer, LENI-tal'!$H$24:$H$32,0),4), O$25='4. Reduktionsfaktorer, LENI-tal'!$S$12,INDEX('4. Reduktionsfaktorer, LENI-tal'!$H$33:$O$37,MATCH(O$27,'4. Reduktionsfaktorer, LENI-tal'!$H$33:$H$37,0),4), O$25='4. Reduktionsfaktorer, LENI-tal'!$T$12,INDEX('4. Reduktionsfaktorer, LENI-tal'!$H$38:$O$45,MATCH(O$27,'4. Reduktionsfaktorer, LENI-tal'!$H$38:$H$45,0),4)), "Fyll i byggnads- och rumstyp ovan")} -> Fyll i byggnads- och rumstyp ovan | P38: {=IFERROR(_xlfn.IFS(P$25='4. Reduktionsfaktorer, LENI-tal'!$Q$12,INDEX('4. Reduktionsfaktorer, LENI-tal'!$H$13:$O$23,MATCH(P$27,'4. Reduktionsfaktorer, LENI-tal'!$H$13:$H$23,0),4), P$25="SKOLA OCH RESTAURANG",INDEX('4. Reduktionsfaktorer, LENI-tal'!$H$24:$O$32,MATCH(P$27,'4. Reduktionsfaktorer, LENI-tal'!$H$24:$H$32,0),4), P$25='4. Reduktionsfaktorer, LENI-tal'!$S$12,INDEX('4. Reduktionsfaktorer, LENI-tal'!$H$33:$O$37,MATCH(P$27,'4. Reduktionsfaktorer, LENI-tal'!$H$33:$H$37,0),4), P$25='4. Reduktionsfaktorer, LENI-tal'!$T$12,INDEX('4. Reduktionsfaktorer, LENI-tal'!$H$38:$O$45,MATCH(P$27,'4. Reduktionsfaktorer, LENI-tal'!$H$38:$H$45,0),4)), "Fyll i byggnads- och rumstyp ovan")} -> Fyll i byggnads- och rumstyp ovan | ... R38: {=IFERROR(_xlfn.IFS(R$25='4. Reduktionsfaktorer, LENI-tal'!$Q$12,INDEX('4. Reduktionsfaktorer, LENI-tal'!$H$13:$O$23,MATCH(R$27,'4. Reduktionsfaktorer, LENI-tal'!$H$13:$H$23,0),4), R$25="SKOLA OCH RESTAURANG",INDEX('4. Reduktionsfaktorer, LENI-tal'!$H$24:$O$32,MATCH(R$27,'4. Reduktionsfaktorer, LENI-tal'!$H$24:$H$32,0),4), R$25='4. Reduktionsfaktorer, LENI-tal'!$S$12,INDEX('4. Reduktionsfaktorer, LENI-tal'!$H$33:$O$37,MATCH(R$27,'4. Reduktionsfaktorer, LENI-tal'!$H$33:$H$37,0),4), R$25='4. Reduktionsfaktorer, LENI-tal'!$T$12,INDEX('4. Reduktionsfaktorer, LENI-tal'!$H$38:$O$45,MATCH(R$27,'4. Reduktionsfaktorer, LENI-tal'!$H$38:$H$45,0),4)), "Fyll i byggnads- och rumstyp ovan")} -> Fyll i byggnads- och rumstyp ovan
B39: 2.8 | C39: Reduktionsfaktor dagsljusstyrning | I39: {=IFERROR(_xlfn.IFS(I$25='4. Reduktionsfaktorer, LENI-tal'!$Q$12,INDEX('4. Reduktionsfaktorer, LENI-tal'!$H$13:$O$23,MATCH(I$27,'4. Reduktionsfaktorer, LENI-tal'!$H$13:$H$23,0),5), I$25="SKOLA OCH RESTAURANG",INDEX('4. Reduktionsfaktorer, LENI-tal'!$H$24:$O$32,MATCH(I$27,'4. Reduktionsfaktorer, LENI-tal'!$H$24:$H$32,0),5), I$25='4. Reduktionsfaktorer, LENI-tal'!$S$12,INDEX('4. Reduktionsfaktorer, LENI-tal'!$H$33:$O$37,MATCH(I$27,'4. Reduktionsfaktorer, LENI-tal'!$H$33:$H$37,0),5), I$25='4. Reduktionsfaktorer, LENI-tal'!$T$12,INDEX('4. Reduktionsfaktorer, LENI-tal'!$H$38:$O$45,MATCH(I$27,'4. Reduktionsfaktorer, LENI-tal'!$H$38:$H$45,0),5)), "Fyll i byggnads- och rumstyp ovan")} -> Fyll i byggnads- och rumstyp ovan | J39: {=IFERROR(_xlfn.IFS(J$25='4. Reduktionsfaktorer, LENI-tal'!$Q$12,INDEX('4. Reduktionsfaktorer, LENI-tal'!$H$13:$O$23,MATCH(J$27,'4. Reduktionsfaktorer, LENI-tal'!$H$13:$H$23,0),5), J$25="SKOLA OCH RESTAURANG",INDEX('4. Reduktionsfaktorer, LENI-tal'!$H$24:$O$32,MATCH(J$27,'4. Reduktionsfaktorer, LENI-tal'!$H$24:$H$32,0),5), J$25='4. Reduktionsfaktorer, LENI-tal'!$S$12,INDEX('4. Reduktionsfaktorer, LENI-tal'!$H$33:$O$37,MATCH(J$27,'4. Reduktionsfaktorer, LENI-tal'!$H$33:$H$37,0),5), J$25='4. Reduktionsfaktorer, LENI-tal'!$T$12,INDEX('4. Reduktionsfaktorer, LENI-tal'!$H$38:$O$45,MATCH(J$27,'4. Reduktionsfaktorer, LENI-tal'!$H$38:$H$45,0),5)), "Fyll i byggnads- och rumstyp ovan")} -> Fyll i byggnads- och rumstyp ovan | K39: {=IFERROR(_xlfn.IFS(K$25='4. Reduktionsfaktorer, LENI-tal'!$Q$12,INDEX('4. Reduktionsfaktorer, LENI-tal'!$H$13:$O$23,MATCH(K$27,'4. Reduktionsfaktorer, LENI-tal'!$H$13:$H$23,0),5), K$25="SKOLA OCH RESTAURANG",INDEX('4. Reduktionsfaktorer, LENI-tal'!$H$24:$O$32,MATCH(K$27,'4. Reduktionsfaktorer, LENI-tal'!$H$24:$H$32,0),5), K$25='4. Reduktionsfaktorer, LENI-tal'!$S$12,INDEX('4. Reduktionsfaktorer, LENI-tal'!$H$33:$O$37,MATCH(K$27,'4. Reduktionsfaktorer, LENI-tal'!$H$33:$H$37,0),5), K$25='4. Reduktionsfaktorer, LENI-tal'!$T$12,INDEX('4. Reduktionsfaktorer, LENI-tal'!$H$38:$O$45,MATCH(K$27,'4. Reduktionsfaktorer, LENI-tal'!$H$38:$H$45,0),5)), "Fyll i byggnads- och rumstyp ovan")} -> Fyll i byggnads- och rumstyp ovan | L39: {=IFERROR(_xlfn.IFS(L$25='4. Reduktionsfaktorer, LENI-tal'!$Q$12,INDEX('4. Reduktionsfaktorer, LENI-tal'!$H$13:$O$23,MATCH(L$27,'4. Reduktionsfaktorer, LENI-tal'!$H$13:$H$23,0),5), L$25="SKOLA OCH RESTAURANG",INDEX('4. Reduktionsfaktorer, LENI-tal'!$H$24:$O$32,MATCH(L$27,'4. Reduktionsfaktorer, LENI-tal'!$H$24:$H$32,0),5), L$25='4. Reduktionsfaktorer, LENI-tal'!$S$12,INDEX('4. Reduktionsfaktorer, LENI-tal'!$H$33:$O$37,MATCH(L$27,'4. Reduktionsfaktorer, LENI-tal'!$H$33:$H$37,0),5), L$25='4. Reduktionsfaktorer, LENI-tal'!$T$12,INDEX('4. Reduktionsfaktorer, LENI-tal'!$H$38:$O$45,MATCH(L$27,'4. Reduktionsfaktorer, LENI-tal'!$H$38:$H$45,0),5)), "Fyll i byggnads- och rumstyp ovan")} -> Fyll i byggnads- och rumstyp ovan | M39: {=IFERROR(_xlfn.IFS(M$25='4. Reduktionsfaktorer, LENI-tal'!$Q$12,INDEX('4. Reduktionsfaktorer, LENI-tal'!$H$13:$O$23,MATCH(M$27,'4. Reduktionsfaktorer, LENI-tal'!$H$13:$H$23,0),5), M$25="SKOLA OCH RESTAURANG",INDEX('4. Reduktionsfaktorer, LENI-tal'!$H$24:$O$32,MATCH(M$27,'4. Reduktionsfaktorer, LENI-tal'!$H$24:$H$32,0),5), M$25='4. Reduktionsfaktorer, LENI-tal'!$S$12,INDEX('4. Reduktionsfaktorer, LENI-tal'!$H$33:$O$37,MATCH(M$27,'4. Reduktionsfaktorer, LENI-tal'!$H$33:$H$37,0),5), M$25='4. Reduktionsfaktorer, LENI-tal'!$T$12,INDEX('4. Reduktionsfaktorer, LENI-tal'!$H$38:$O$45,MATCH(M$27,'4. Reduktionsfaktorer, LENI-tal'!$H$38:$H$45,0),5)), "Fyll i byggnads- och rumstyp ovan")} -> Fyll i byggnads- och rumstyp ovan | N39: {=IFERROR(_xlfn.IFS(N$25='4. Reduktionsfaktorer, LENI-tal'!$Q$12,INDEX('4. Reduktionsfaktorer, LENI-tal'!$H$13:$O$23,MATCH(N$27,'4. Reduktionsfaktorer, LENI-tal'!$H$13:$H$23,0),5), N$25="SKOLA OCH RESTAURANG",INDEX('4. Reduktionsfaktorer, LENI-tal'!$H$24:$O$32,MATCH(N$27,'4. Reduktionsfaktorer, LENI-tal'!$H$24:$H$32,0),5), N$25='4. Reduktionsfaktorer, LENI-tal'!$S$12,INDEX('4. Reduktionsfaktorer, LENI-tal'!$H$33:$O$37,MATCH(N$27,'4. Reduktionsfaktorer, LENI-tal'!$H$33:$H$37,0),5), N$25='4. Reduktionsfaktorer, LENI-tal'!$T$12,INDEX('4. Reduktionsfaktorer, LENI-tal'!$H$38:$O$45,MATCH(N$27,'4. Reduktionsfaktorer, LENI-tal'!$H$38:$H$45,0),5)), "Fyll i byggnads- och rumstyp ovan")} -> Fyll i byggnads- och rumstyp ovan | O39: {=IFERROR(_xlfn.IFS(O$25='4. Reduktionsfaktorer, LENI-tal'!$Q$12,INDEX('4. Reduktionsfaktorer, LENI-tal'!$H$13:$O$23,MATCH(O$27,'4. Reduktionsfaktorer, LENI-tal'!$H$13:$H$23,0),5), O$25="SKOLA OCH RESTAURANG",INDEX('4. Reduktionsfaktorer, LENI-tal'!$H$24:$O$32,MATCH(O$27,'4. Reduktionsfaktorer, LENI-tal'!$H$24:$H$32,0),5), O$25='4. Reduktionsfaktorer, LENI-tal'!$S$12,INDEX('4. Reduktionsfaktorer, LENI-tal'!$H$33:$O$37,MATCH(O$27,'4. Reduktionsfaktorer, LENI-tal'!$H$33:$H$37,0),5), O$25='4. Reduktionsfaktorer, LENI-tal'!$T$12,INDEX('4. Reduktionsfaktorer, LENI-tal'!$H$38:$O$45,MATCH(O$27,'4. Reduktionsfaktorer, LENI-tal'!$H$38:$H$45,0),5)), "Fyll i byggnads- och rumstyp ovan")} -> Fyll i byggnads- och rumstyp ovan | P39: {=IFERROR(_xlfn.IFS(P$25='4. Reduktionsfaktorer, LENI-tal'!$Q$12,INDEX('4. Reduktionsfaktorer, LENI-tal'!$H$13:$O$23,MATCH(P$27,'4. Reduktionsfaktorer, LENI-tal'!$H$13:$H$23,0),5), P$25="SKOLA OCH RESTAURANG",INDEX('4. Reduktionsfaktorer, LENI-tal'!$H$24:$O$32,MATCH(P$27,'4. Reduktionsfaktorer, LENI-tal'!$H$24:$H$32,0),5), P$25='4. Reduktionsfaktorer, LENI-tal'!$S$12,INDEX('4. Reduktionsfaktorer, LENI-tal'!$H$33:$O$37,MATCH(P$27,'4. Reduktionsfaktorer, LENI-tal'!$H$33:$H$37,0),5), P$25='4. Reduktionsfaktorer, LENI-tal'!$T$12,INDEX('4. Reduktionsfaktorer, LENI-tal'!$H$38:$O$45,MATCH(P$27,'4. Reduktionsfaktorer, LENI-tal'!$H$38:$H$45,0),5)), "Fyll i byggnads- och rumstyp ovan")} -> Fyll i byggnads- och rumstyp ovan | ... R39: {=IFERROR(_xlfn.IFS(R$25='4. Reduktionsfaktorer, LENI-tal'!$Q$12,INDEX('4. Reduktionsfaktorer, LENI-tal'!$H$13:$O$23,MATCH(R$27,'4. Reduktionsfaktorer, LENI-tal'!$H$13:$H$23,0),5), R$25="SKOLA OCH RESTAURANG",INDEX('4. Reduktionsfaktorer, LENI-tal'!$H$24:$O$32,MATCH(R$27,'4. Reduktionsfaktorer, LENI-tal'!$H$24:$H$32,0),5), R$25='4. Reduktionsfaktorer, LENI-tal'!$S$12,INDEX('4. Reduktionsfaktorer, LENI-tal'!$H$33:$O$37,MATCH(R$27,'4. Reduktionsfaktorer, LENI-tal'!$H$33:$H$37,0),5), R$25='4. Reduktionsfaktorer, LENI-tal'!$T$12,INDEX('4. Reduktionsfaktorer, LENI-tal'!$H$38:$O$45,MATCH(R$27,'4. Reduktionsfaktorer, LENI-tal'!$H$38:$H$45,0),5)), "Fyll i byggnads- och rumstyp ovan")} -> Fyll i byggnads- och rumstyp ovan
B40: 2.9 | C40: Total reduktionsfaktor för styrning | I40: =IF(IF(I36=$I$238,I37,IF(I36=$I$239,I37*I38,IF(I36=$I$240,I37*I38*I39,1)))=0,"Fyll i 2.6-2.8",IF(I36=$I$238,I37,IF(I36=$I$239,I37*I38,IF(I36=$I$240,I37*I38*I39,1)))) -> 1 | J40: =IF(IF(J36=$I$238,J37,IF(J36=$I$239,J37*J38,IF(J36=$I$240,J37*J38*J39,1)))=0,"Fyll i 2.6-2.8",IF(J36=$I$238,J37,IF(J36=$I$239,J37*J38,IF(J36=$I$240,J37*J38*J39,1)))) -> 1 | K40: =IF(IF(K36=$I$238,K37,IF(K36=$I$239,K37*K38,IF(K36=$I$240,K37*K38*K39,1)))=0,"Fyll i 2.6-2.8",IF(K36=$I$238,K37,IF(K36=$I$239,K37*K38,IF(K36=$I$240,K37*K38*K39,1)))) -> 1 | L40: =IF(IF(L36=$I$238,L37,IF(L36=$I$239,L37*L38,IF(L36=$I$240,L37*L38*L39,1)))=0,"Fyll i 2.6-2.8",IF(L36=$I$238,L37,IF(L36=$I$239,L37*L38,IF(L36=$I$240,L37*L38*L39,1)))) -> 1 | M40: =IF(IF(M36=$I$238,M37,IF(M36=$I$239,M37*M38,IF(M36=$I$240,M37*M38*M39,1)))=0,"Fyll i 2.6-2.8",IF(M36=$I$238,M37,IF(M36=$I$239,M37*M38,IF(M36=$I$240,M37*M38*M39,1)))) -> 1 | N40: =IF(IF(N36=$I$238,N37,IF(N36=$I$239,N37*N38,IF(N36=$I$240,N37*N38*N39,1)))=0,"Fyll i 2.6-2.8",IF(N36=$I$238,N37,IF(N36=$I$239,N37*N38,IF(N36=$I$240,N37*N38*N39,1)))) -> 1 | O40: =IF(IF(O36=$I$238,O37,IF(O36=$I$239,O37*O38,IF(O36=$I$240,O37*O38*O39,1)))=0,"Fyll i 2.6-2.8",IF(O36=$I$238,O37,IF(O36=$I$239,O37*O38,IF(O36=$I$240,O37*O38*O39,1)))) -> 1 | P40: =IF(IF(P36=$I$238,P37,IF(P36=$I$239,P37*P38,IF(P36=$I$240,P37*P38*P39,1)))=0,"Fyll i 2.6-2.8",IF(P36=$I$238,P37,IF(P36=$I$239,P37*P38,IF(P36=$I$240,P37*P38*P39,1)))) -> 1 | ... R40: =IF(IF(R36=$I$238,R37,IF(R36=$I$239,R37*R38,IF(R36=$I$240,R37*R38*R39,1)))=0,"Fyll i 2.6-2.8",IF(R36=$I$238,R37,IF(R36=$I$239,R37*R38,IF(R36=$I$240,R37*R38*R39,1)))) -> 1
B41: 2.10 | C41: Underhållskostnader | H41: kr/år
C43: ARMATURTYP 2
B44: 2.1 | C44: Antal armaturer | H44: stk
B45: 2.2 | C45: Armaturpris | H45: kr/stk
B46: 2.3 | C46: Material- och arbetskostnader armatur | H46: kr/stk
B47: 2.4 | C47: Effekt per armatur, inkl. driftsförluster | H47: W/stk
...

Sheet 2. LCC A3
A1: (PW: LCC)
G2: LCC-kalkyl för upphandling av inomhusbelysning
G3: ='1. Introduktion'!G3 -> Version 3.0
G4: ='1. Introduktion'!G4 -> Datum: 2024-12-17
C8: LCC-kalkyl Anläggning alternativ 3
C10: Kalkylförutsättningar (anges av beställaren) | K10: Byggnadstyp | L10: 0
C11: PROJEKT: | F11: Projektnamn | K11: Kontor | L11: 2500
C12: DATUM: | F12: ÅÅÅÅ-MM-DD | K12: Skola, restaurang | L12: 2000
C13: HANDLÄGGARE: | F13: Namn | K13: Sporthall | L13: 4000
K14: Vård | L14: 5000
B15: 1.1 | C15: Tid kalkylen omfattar | I15: år
B16: 1.2 | C16: Kalkylränta | H16: 0.05 | K16: Indata till fält 16: Byggnadens driftitid h/ år
B17: 1.3 | C17: Elpris | I17: kr/kWh | K17: Byggnadstyp | L17: Byggnadstyp
B18: 1.4 | C18: Årlig prisförändring energi (frivillig) | K18: Eget värde för drifttid h/år
B19: 1.5 | C19: Klimatpåverkan energianvändning (frivillig) | I19: kgCO2/kwh | K19: Driftitd timmar per år | L19: =IF(ISBLANK($L$18),VLOOKUP($L$17,$K$10:$L$14,2),$L$18) -> 0
B20: 1.6 | C20: Drifttid | H20: =$L$19 -> 0 | I20: h/år
C22: Beskrivning av anläggningen och belysningsförslag
C24: BESKRIVNING AV ANLÄGGNINGEN (anges av beställaren)
C25: Byggnadstyp | I25: Byggnadstyp 1 | J25: Byggnadstyp 2 | K25: Byggnadstyp 3 | L25: Byggnadstyp 4 | M25: Byggnadstyp 5 | N25: Byggnadstyp 6 | O25: Byggnadstyp 7 | P25: Byggnadstyp 8 | Q25: Byggnadstyp 9 | R25: Byggnadstyp 10
C26: Byggnadstyp hjälprad | I26: =SUBSTITUTE(I25," ","_") -> Byggnadstyp_1 | J26: =SUBSTITUTE(J25," ","_") -> Byggnadstyp_2 | K26: =SUBSTITUTE(K25," ","_") -> Byggnadstyp_3 | L26: =SUBSTITUTE(L25," ","_") -> Byggnadstyp_4 | M26: =SUBSTITUTE(M25," ","_") -> Byggnadstyp_5 | N26: =SUBSTITUTE(N25," ","_") -> Byggnadstyp_6 | O26: =SUBSTITUTE(O25," ","_") -> Byggnadstyp_7 | P26: =SUBSTITUTE(P25," ","_") -> Byggnadstyp_8 | ... R26: =SUBSTITUTE(R25," ","_") -> Byggnadstyp_10
C27: Rumstyp (välj byggnadstyp ovan för att få lista med giltiga rumstyper) | I27: Rumstyp 1 | J27: Rumstyp 2 | K27: Rumstyp 3 | L27: Rumstyp 4 | M27: Rumstyp 5 | N27: Rumstyp 6 | O27: Rumstyp 7 | P27: Rumstyp 8 | Q27: Rumstyp 9 | R27: Rumstyp 10
C28: Antal rum av samma typ | H28: stk | I28: 1 | J28: 1 | K28: 1 | L28: 1 | M28: 1 | N28: 1 | O28: 1 | P28: 1 | Q28: 1 | R28: 1
C29: Antal kvadratmeter | H29: m2/rum | I29: 1 | J29: 1 | K29: 1 | L29: 1 | M29: 1 | N29: 1 | O29: 1 | P29: 1 | Q29: 1 | R29: 1
C30: BELYSNINGSFÖRSLAG (anges av anbudsgivaren)
C31: ARMATURTYP 1
B32: 2.1 | C32: Antal armaturer | H32: stk
B33: 2.2 | C33: Armaturpris | H33: kr/stk
B34: 2.3 | C34: Material- och arbetskostnader armatur | H34: kr/stk
B35: 2.4 | C35: Effekt per armatur, inkl. driftsförluster | H35: W/stk
B36: 2.5 | C36: Typ av styrning | I36: Ingen | J36: Ingen | K36: Ingen | L36: Ingen | M36: Ingen | N36: Ingen | O36: Ingen | P36: Ingen | Q36: Ingen | R36: Ingen
